[ERROR]: 2013-02-19 15:11:00,530, generatereport, error occured during generating report,traceback:Traceback (most recent call last):
  File "/home/uls/workplace/atplatform/atplatform/report/planresult.py", line 49, in generatereport
    shutil.copytree(cp.basereportlocation,path)
  File "/usr/lib/python2.7/shutil.py", line 169, in copytree
    names = os.listdir(src)
OSError: [Errno 2] No such file or directory: 'C:\\workplace\\atplatform\\report\\basereport\\'

[ERROR]: 2013-02-19 15:11:00,540, callback, error occured during process report for plan:test30,error:Traceback (most recent call last):
  File "/home/uls/workplace/atplatform/atplatform/report/receive.py", line 22, in callback
    tempplanresult.generatereport()
  File "/home/uls/workplace/atplatform/atplatform/report/planresult.py", line 58, in generatereport
    raise Exception(traceback.format_exc())
Exception: Traceback (most recent call last):
  File "/home/uls/workplace/atplatform/atplatform/report/planresult.py", line 49, in generatereport
    shutil.copytree(cp.basereportlocation,path)
  File "/usr/lib/python2.7/shutil.py", line 169, in copytree
    names = os.listdir(src)
OSError: [Errno 2] No such file or directory: 'C:\\workplace\\atplatform\\report\\basereport\\'


[ERROR]: 2013-02-19 15:14:36,583, generatereport, error occured during generating report,traceback:Traceback (most recent call last):
  File "/home/uls/workplace/atplatform/atplatform/report/planresult.py", line 42, in generatereport
    filetemp=file(cp.resultstmplocation+self.planname,'w')
IOError: [Errno 2] No such file or directory: '/home/uls/workplace/atplatform/atplatform/report/temp/test31'

[ERROR]: 2013-02-19 15:14:36,593, callback, error occured during process report for plan:test31,error:Traceback (most recent call last):
  File "/home/uls/workplace/atplatform/atplatform/report/receive.py", line 22, in callback
    tempplanresult.generatereport()
  File "/home/uls/workplace/atplatform/atplatform/report/planresult.py", line 58, in generatereport
    raise Exception(traceback.format_exc())
Exception: Traceback (most recent call last):
  File "/home/uls/workplace/atplatform/atplatform/report/planresult.py", line 42, in generatereport
    filetemp=file(cp.resultstmplocation+self.planname,'w')
IOError: [Errno 2] No such file or directory: '/home/uls/workplace/atplatform/atplatform/report/temp/test31'


[ERROR]: 2013-02-20 01:07:47,991, generatereport, error occured during generating report,traceback:Traceback (most recent call last):
  File "/home/uls/workplace/atplatform/atplatform/report/planresult.py", line 42, in generatereport
    filetemp=file(cp.resultstmplocation+self.planname,'w')
IOError: [Errno 2] No such file or directory: '/home/uls/workplace/atplatform/atplatform/report/temp/test34'

[ERROR]: 2013-02-20 01:07:48,011, callback, error occured during process report for plan:test34,error:Traceback (most recent call last):
  File "/home/uls/workplace/atplatform/atplatform/report/receive.py", line 22, in callback
    tempplanresult.generatereport()
  File "/home/uls/workplace/atplatform/atplatform/report/planresult.py", line 58, in generatereport
    raise Exception(traceback.format_exc())
Exception: Traceback (most recent call last):
  File "/home/uls/workplace/atplatform/atplatform/report/planresult.py", line 42, in generatereport
    filetemp=file(cp.resultstmplocation+self.planname,'w')
IOError: [Errno 2] No such file or directory: '/home/uls/workplace/atplatform/atplatform/report/temp/test34'


